Workbook

Sheet Student
A1: Student_ID | B1: First_Name | C1: Last_Name | D1: Gender | E1: Age | F1: Class | G1: Section | H1: City | I1: Admission_Date | J1: Marks
A2: S0001 | B2: Sneha | C2: Paul | D2: Male | E2: 16 | F2: 10 | G2: B | H2: Pune | I2: 2024-10-06 | J2: 37
A3: S0002 | B3: Amit | C3: Das | D3: Male | E3: 15 | F3: 12 | G3: B | H3: Jaipur | I3: 2024-11-06 | J3: 98
A4: S0003 | B4: Karan | C4: Roy | D4: Male | E4: 14 | F4: 12 | G4: D | H4: Kolkata | I4: 2024-10-12 | J4: 38
A5: S0004 | B5: Priya | C5: Singh | D5: Female | E5: 20 | F5: 9 | G5: A | H5: Kolkata | I5: 2023-06-14 | J5: 84
A6: S0005 | B6: Neha | C6: Kumar | D6: Female | E6: 17 | F6: 10 | G6: A | H6: Bengaluru | I6: 2023-09-21 | J6: 45
A7: S0006 | B7: Sneha | C7: Paul | D7: Female | E7: 19 | F7: 10 | G7: B | H7: Hyderabad | I7: 2023-09-12 | J7: 36
A8: S0007 | B8: Priya | C8: Roy | D8: Female | E8: 20 | F8: 9 | G8: C | H8: Hyderabad | I8: 2025-08-17 | J8: 88
A9: S0008 | B9: Neha | C9: Paul | D9: Male | E9: 19 | F9: 12 | G9: A | H9: Mumbai | I9: 2025-01-28 | J9: 60
A10: S0009 | B10: Amit | C10: Singh | D10: Female | E10: 19 | F10: 12 | G10: B | H10: Mumbai | I10: 2023-06-04 | J10: 92
A11: S0010 | B11: Arjun | C11: Roy | D11: Female | E11: 15 | F11: 9 | G11: C | H11: Pune | I11: 2025-03-19 | J11: 90
A12: S0011 | B12: Riya | C12: Gupta | D12: Female | E12: 20 | F12: 10 | G12: D | H12: Hyderabad | I12: 2024-10-08 | J12: 59
A13: S0012 | B13: Arjun | C13: Patel | D13: Male | E13: 14 | F13: 12 | G13: A | H13: Hyderabad | I13: 2024-08-18 | J13: 43
... A501: S0500 | B501: Arjun | C501: Mishra | D501: Female | E501: 18 | F501: 9 | G501: C | H501: Chennai | I501: 2023-08-05 | J501: 36

Sheet FORMULAS
A1: 1. Count the total number of students.
B3: no_of_students | C3: =COUNTA(Student!A2:A501) -> 500
A5: 1. Find the highest marks scored.
B7: Highest Marks | C7: =MAX(Student!J2:J501) -> 100
A9: 2. Find the lowest marks scored.
B11: Lowest Marks | C11: =MIN(Student!J2:J501) -> 35
A13: 3. Calculate the average marks of all students.
B15: Average Marks | C15: =AVERAGE(Student!J2:J501) -> 66.508
A17: 4. Count the number of male and female students.
B19: Male Students | C19: =COUNTIF(Student!D2:D501,"male") -> 229
B20: Female Students | C20: =COUNTIF(Student!D2:D501,"female") -> 271
A22: 5. Find the average age of students.
B24: Average_Age_of_students | C24: =AVERAGE(Student!E2:E501) -> 16.976
A26: 1. Count students from Kolkata.
B28: students from kolkata | C28: =COUNTIF(Student!H2:H501,"Kolkata") -> 57
A30: 2. Count students scoring above 80.
B32: students scoring above 80 | C32: =COUNTIF(Student!J2:J501,">80") -> 150
A34: 3. Count female students in Class 12.
B36: female students in Class 12 | C36: =COUNTIFS(Student!D2:D501,"Female",Student!F2:F501,"12") -> 72
A38: 4. Count male students from Delhi scoring above 70.
B40: male students from Delhi scoring above 70 | C40: =COUNTIFS(Student!D2:D501,"Male",Student!H2:H501,"Delhi",Student!J2:J501,">70") -> 17
A42: 5. Calculate average marks of students from Kolkata.
B44: average marks of students from Kolkata | C44: =AVERAGEIF(Student!H2:H501,"Kolkata",Student!J2:J501) -> 65.052632
A46: 6. Calculate average marks of female students.
B48: average marks of female students | C48: =AVERAGEIF(Student!D2:D501,"Female",Student!J2:J501) -> 66.121771
A50: 7. Calculate total marks of Class 10 students.
B52: total marks of class 10 | C52: =SUMIF(Student!F2:F501,"10",Student!J2:J501) -> 7624
A54: 8. Calculate average age of students from Mumbai.
B56: average age of students from mumbai | C56: =AVERAGEIF(Student!H2:H501,"Mumbai",Student!E2:E501) -> 17.15942

Sheet newcolumns
A1: Student_ID | B1: First_Name | C1: Last_Name | D1: Gender | E1: Age | F1: Class | G1: Section | H1: City | I1: Admission_Date | J1: Marks | K1: Result | L1: Grade | N1: 16. Create a new column named Result.
A2: S0001 | B2: Sneha | C2: Paul | D2: Male | E2: 16 | F2: 10 | G2: B | H2: Pune | I2: 2024-10-06 | J2: 37 | K2: =IF(J2>=40,"pass","fail") -> fail | L2: =IF(J2>=90,"A+",IF(J2>=80,"A",IF(J2>=70,"B",IF(J2>=60,"C",IF(J2>=50,"D",IF(J2>=40,"E","F")))))) -> F | N2: 17 | O2: Create a Grade column
A3: S0002 | B3: Amit | C3: Das | D3: Male | E3: 15 | F3: 12 | G3: B | H3: Jaipur | I3: 2024-11-06 | J3: 98 | K3: =IF(J3>=40,"pass","fail") -> pass | L3: =IF(J3>=90,"A+",IF(J3>=80,"A",IF(J3>=70,"B",IF(J3>=60,"C",IF(J3>=50,"D",IF(J3>=40,"E","F")))))) -> A+
A4: S0003 | B4: Karan | C4: Roy | D4: Male | E4: 14 | F4: 12 | G4: D | H4: Kolkata | I4: 2024-10-12 | J4: 38 | K4: =IF(J4>=40,"pass","fail") -> fail | L4: =IF(J4>=90,"A+",IF(J4>=80,"A",IF(J4>=70,"B",IF(J4>=60,"C",IF(J4>=50,"D",IF(J4>=40,"E","F")))))) -> F
A5: S0004 | B5: Priya | C5: Singh | D5: Female | E5: 20 | F5: 9 | G5: A | H5: Kolkata | I5: 2023-06-14 | J5: 84 | K5: =IF(J5>=40,"pass","fail") -> pass | L5: =IF(J5>=90,"A+",IF(J5>=80,"A",IF(J5>=70,"B",IF(J5>=60,"C",IF(J5>=50,"D",IF(J5>=40,"E","F")))))) -> A
A6: S0005 | B6: Neha | C6: Kumar | D6: Female | E6: 17 | F6: 10 | G6: A | H6: Bengaluru | I6: 2023-09-21 | J6: 45 | K6: =IF(J6>=40,"pass","fail") -> pass | L6: =IF(J6>=90,"A+",IF(J6>=80,"A",IF(J6>=70,"B",IF(J6>=60,"C",IF(J6>=50,"D",IF(J6>=40,"E","F")))))) -> E
A7: S0006 | B7: Sneha | C7: Paul | D7: Female | E7: 19 | F7: 10 | G7: B | H7: Hyderabad | I7: 2023-09-12 | J7: 36 | K7: =IF(J7>=40,"pass","fail") -> fail | L7: =IF(J7>=90,"A+",IF(J7>=80,"A",IF(J7>=70,"B",IF(J7>=60,"C",IF(J7>=50,"D",IF(J7>=40,"E","F")))))) -> F
A8: S0007 | B8: Priya | C8: Roy | D8: Female | E8: 20 | F8: 9 | G8: C | H8: Hyderabad | I8: 2025-08-17 | J8: 88 | K8: =IF(J8>=40,"pass","fail") -> pass | L8: =IF(J8>=90,"A+",IF(J8>=80,"A",IF(J8>=70,"B",IF(J8>=60,"C",IF(J8>=50,"D",IF(J8>=40,"E","F")))))) -> A
A9: S0008 | B9: Neha | C9: Paul | D9: Male | E9: 19 | F9: 12 | G9: A | H9: Mumbai | I9: 2025-01-28 | J9: 60 | K9: =IF(J9>=40,"pass","fail") -> pass | L9: =IF(J9>=90,"A+",IF(J9>=80,"A",IF(J9>=70,"B",IF(J9>=60,"C",IF(J9>=50,"D",IF(J9>=40,"E","F")))))) -> C
A10: S0009 | B10: Amit | C10: Singh | D10: Female | E10: 19 | F10: 12 | G10: B | H10: Mumbai | I10: 2023-06-04 | J10: 92 | K10: =IF(J10>=40,"pass","fail") -> pass | L10: =IF(J10>=90,"A+",IF(J10>=80,"A",IF(J10>=70,"B",IF(J10>=60,"C",IF(J10>=50,"D",IF(J10>=40,"E","F")))))) -> A+
A11: S0010 | B11: Arjun | C11: Roy | D11: Female | E11: 15 | F11: 9 | G11: C | H11: Pune | I11: 2025-03-19 | J11: 90 | K11: =IF(J11>=40,"pass","fail") -> pass | L11: =IF(J11>=90,"A+",IF(J11>=80,"A",IF(J11>=70,"B",IF(J11>=60,"C",IF(J11>=50,"D",IF(J11>=40,"E","F")))))) -> A+
A12: S0011 | B12: Riya | C12: Gupta | D12: Female | E12: 20 | F12: 10 | G12: D | H12: Hyderabad | I12: 2024-10-08 | J12: 59 | K12: =IF(J12>=40,"pass","fail") -> pass | L12: =IF(J12>=90,"A+",IF(J12>=80,"A",IF(J12>=70,"B",IF(J12>=60,"C",IF(J12>=50,"D",IF(J12>=40,"E","F")))))) -> D
A13: S0012 | B13: Arjun | C13: Patel | D13: Male | E13: 14 | F13: 12 | G13: A | H13: Hyderabad | I13: 2024-08-18 | J13: 43 | K13: =IF(J13>=40,"pass","fail") -> pass | L13: =IF(J13>=90,"A+",IF(J13>=80,"A",IF(J13>=70,"B",IF(J13>=60,"C",IF(J13>=50,"D",IF(J13>=40,"E","F")))))) -> E
A14: S0013 | B14: Neha | C14: Gupta | D14: Male | E14: 15 | F14: 12 | G14: B | H14: Delhi | I14: 2024-04-25 | J14: 51 | K14: =IF(J14>=40,"pass","fail") -> pass | L14: =IF(J14>=90,"A+",IF(J14>=80,"A",IF(J14>=70,"B",IF(J14>=60,"C",IF(J14>=50,"D",IF(J14>=40,"E","F")))))) -> D
... A501: S0500 | B501: Arjun | C501: Mishra | D501: Female | E501: 18 | F501: 9 | G501: C | H501: Chennai | I501: 2023-08-05 | J501: 36 | K501: =IF(J501>=40,"pass","fail") -> fail | L501: =IF(J501>=90,"A+",IF(J501>=80,"A",IF(J501>=70,"B",IF(J501>=60,"C",IF(J501>=50,"D",IF(J501>=40,"E","F")))))) -> F

Sheet sorting
A1: 6. Sort students by Marks (Highest to Lowest). | M1: 7. Sort students by Age (Lowest to Highest).
A3: Student_ID | B3: First_Name | C3: Last_Name | D3: Gender | E3: Age | F3: Class | G3: Section | H3: City | I3: Admission_Date | J3: Marks | M3: Student_ID | N3: First_Name | O3: Last_Name | P3: Gender | Q3: Age | R3: Class | S3: Section | T3: City | U3: Admission_Date | V3: Marks
A4: S0048 | B4: Arjun | C4: Sharma | D4: Male | E4: 18 | F4: 11 | G4: C | H4: Delhi | I4: 2024-08-25 | J4: 100 | M4: S0003 | N4: Karan | O4: Roy | P4: Male | Q4: 14 | R4: 12 | S4: D | T4: Kolkata | U4: 2024-10-12 | V4: 38
A5: S0101 | B5: Riya | C5: Sharma | D5: Female | E5: 15 | F5: 12 | G5: B | H5: Hyderabad | I5: 2024-05-22 | J5: 100 | M5: S0012 | N5: Arjun | O5: Patel | P5: Male | Q5: 14 | R5: 12 | S5: A | T5: Hyderabad | U5: 2024-08-18 | V5: 43
A6: S0128 | B6: Pooja | C6: Mishra | D6: Female | E6: 20 | F6: 9 | G6: C | H6: Kolkata | I6: 2024-05-30 | J6: 100 | M6: S0017 | N6: Arjun | O6: Kumar | P6: Male | Q6: 14 | R6: 12 | S6: D | T6: Bengaluru | U6: 2023-09-19 | V6: 42
A7: S0130 | B7: Rahul | C7: Das | D7: Female | E7: 20 | F7: 10 | G7: C | H7: Jaipur | I7: 2025-08-05 | J7: 100 | M7: S0026 | N7: Priya | O7: Roy | P7: Female | Q7: 14 | R7: 12 | S7: A | T7: Delhi | U7: 2023-11-06 | V7: 72
A8: S0188 | B8: Priya | C8: Paul | D8: Female | E8: 16 | F8: 10 | G8: B | H8: Hyderabad | I8: 2023-09-19 | J8: 100 | M8: S0034 | N8: Arjun | O8: Patel | P8: Female | Q8: 14 | R8: 10 | S8: A | T8: Chennai | U8: 2023-10-12 | V8: 60
A9: S0283 | B9: Riya | C9: Paul | D9: Female | E9: 17 | F9: 9 | G9: D | H9: Bengaluru | I9: 2024-09-06 | J9: 100 | M9: S0047 | N9: Sneha | O9: Ghosh | P9: Male | Q9: 14 | R9: 10 | S9: C | T9: Delhi | U9: 2024-09-04 | V9: 65
A10: S0397 | B10: Priya | C10: Sharma | D10: Female | E10: 20 | F10: 10 | G10: B | H10: Mumbai | I10: 2024-08-16 | J10: 100 | M10: S0062 | N10: Rahul | O10: Roy | P10: Male | Q10: 14 | R10: 10 | S10: C | T10: Pune | U10: 2024-10-01 | V10: 45
A11: S0059 | B11: Arjun | C11: Sharma | D11: Female | E11: 17 | F11: 11 | G11: C | H11: Bengaluru | I11: 2024-05-21 | J11: 99 | M11: S0065 | N11: Priya | O11: Sharma | P11: Male | Q11: 14 | R11: 10 | S11: A | T11: Delhi | U11: 2023-01-05 | V11: 51
A12: S0068 | B12: Priya | C12: Patel | D12: Female | E12: 19 | F12: 12 | G12: C | H12: Delhi | I12: 2025-07-15 | J12: 99 | M12: S0072 | N12: Neha | O12: Singh | P12: Female | Q12: 14 | R12: 12 | S12: C | T12: Delhi | U12: 2025-08-28 | V12: 45
A13: S0129 | B13: Neha | C13: Gupta | D13: Male | E13: 20 | F13: 9 | G13: D | H13: Mumbai | I13: 2024-07-16 | J13: 99 | M13: S0075 | N13: Amit | O13: Das | P13: Female | Q13: 14 | R13: 12 | S13: A | T13: Bengaluru | U13: 2025-02-17 | V13: 63
A14: S0167 | B14: Neha | C14: Paul | D14: Female | E14: 15 | F14: 10 | G14: A | H14: Jaipur | I14: 2024-02-27 | J14: 99 | M14: S0079 | N14: Sneha | O14: Sharma | P14: Female | Q14: 14 | R14: 10 | S14: D | T14: Delhi | U14: 2024-01-21 | V14: 97
A15: S0197 | B15: Pooja | C15: Mishra | D15: Male | E15: 14 | F15: 10 | G15: D | H15: Pune | I15: 2023-10-21 | J15: 99 | M15: S0091 | N15: Arjun | O15: Gupta | P15: Male | Q15: 14 | R15: 10 | S15: C | T15: Delhi | U15: 2025-04-15 | V15: 72
... A503: S0459 | B503: Neha | C503: Kumar | D503: Male | E503: 16 | F503: 10 | G503: B | H503: Delhi | I503: 2024-12-28 | J503: 35 | M503: S0497 | N503: Amit | O503: Paul | P503: Male | Q503: 20 | R503: 11 | S503: C | T503: Mumbai | U503: 2024-10-15 | V503: 94

Sheet filter
A1: 8. Filter students from Kolkata. | M1: 9. Display students who scored above 80 marks. | Y1: 10. Display only female students from Class 12. | AL1: 1. Extract students from Kolkata. | AY1: 2. Extract students with Marks > 80. | BL1: 3. Extract female students from Class 12. | BY1: 4. Extract students aged between 16 and 18. | CL1: 5. Extract students from Mumbai or Delhi.
A3: City | M3: Marks | Z3: Gender | AA3: Class | AM3: City | AZ3: Marks | BM3: Gender | BN3: Class | BZ3: Age | CA3: Age | CM3: City
A4: Kolkata | M4: >80 | Z4: Female | AA4: 12 | AM4: Kolkata | AZ4: >80 | BM4: Female | BN4: 12 | BZ4: >=16 | CA4: <=18 | CM4: Mumbai
CM5: Delhi
A6: Student_ID | B6: First_Name | C6: Last_Name | D6: Gender | E6: Age | F6: Class | G6: Section | H6: City | I6: Admission_Date | J6: Marks | M6: Student_ID | N6: First_Name | O6: Last_Name | P6: Gender | Q6: Age | R6: Class | S6: Section | T6: City | U6: Admission_Date | V6: Marks | Z6: Student_ID | AA6: First_Name | AB6: Last_Name | AC6: Gender | AD6: Age | AE6: Class | AF6: Section | AG6: City | AH6: Admission_Date | AI6: Marks | AM6: Student_ID | AN6: First_Name | AO6: Last_Name | AP6: Gender | AQ6: Age | AR6: Class | AS6: Section | AT6: City | AU6: Admission_Date | AV6: Marks | AZ6: Student_ID | BA6: First_Name | BB6: Last_Name | BC6: Gender | BD6: Age | BE6: Class | BF6: Section | BG6: City | BH6: Admission_Date | BI6: Marks | BM6: Student_ID | BN6: First_Name | BO6: Last_Name | BP6: Gender | BQ6: Age | BR6: Class | BS6: Section | BT6: City | BU6: Admission_Date | BV6: Marks | BZ6: Student_ID | CA6: First_Name | CB6: Last_Name | CC6: Gender | CD6: Age | CE6: Class | CF6: Section | CG6: City | CH6: Admission_Date | CI6: Marks
A7: S0003 | B7: Karan | C7: Roy | D7: Male | E7: 14 | F7: 12 | G7: D | H7: Kolkata | I7: 2024-10-12 | J7: 38 | M7: S0002 | N7: Amit | O7: Das | P7: Male | Q7: 15 | R7: 12 | S7: B | T7: Jaipur | U7: 2024-11-06 | V7: 98 | Z7: S0009 | AA7: Amit | AB7: Singh | AC7: Female | AD7: 19 | AE7: 12 | AF7: B | AG7: Mumbai | AH7: 2023-06-04 | AI7: 92 | AM7: S0003 | AN7: Karan | AO7: Roy | AP7: Male | AQ7: 14 | AR7: 12 | AS7: D | AT7: Kolkata | AU7: 2024-10-12 | AV7: 38 | AZ7: S0002 | BA7: Amit | BB7: Das | BC7: Male | BD7: 15 | BE7: 12 | BF7: B | BG7: Jaipur | BH7: 2024-11-06 | BI7: 98 | BM7: S0009 | BN7: Amit | BO7: Singh | BP7: Female | BQ7: 19 | BR7: 12 | BS7: B | BT7: Mumbai | BU7: 2023-06-04 | BV7: 92 | BZ7: S0001 | CA7: Sneha | CB7: Paul | CC7: Male | CD7: 16 | CE7: 10 | CF7: B | CG7: Pune | CH7: 2024-10-06 | CI7: 37 | CM7: Student_ID | CN7: First_Name | CO7: Last_Name | CP7: Gender | CQ7: Age | CR7: Class | CS7: Section | CT7: City | CU7: Admission_Date | CV7: Marks
A8: S0004 | B8: Priya | C8: Singh | D8: Female | E8: 20 | F8: 9 | G8: A | H8: Kolkata | I8: 2023-06-14 | J8: 84 | M8: S0004 | N8: Priya | O8: Singh | P8: Female | Q8: 20 | R8: 9 | S8: A | T8: Kolkata | U8: 2023-06-14 | V8: 84 | Z8: S0019 | AA8: Priya | AB8: Patel | AC8: Female | AD8: 17 | AE8: 12 | AF8: A | AG8: Chennai | AH8: 2025-04-12 | AI8: 66 | AM8: S0004 | AN8: Priya | AO8: Singh | AP8: Female | AQ8: 20 | AR8: 9 | AS8: A | AT8: Kolkata | AU8: 2023-06-14 | AV8: 84 | AZ8: S0004 | BA8: Priya | BB8: Singh | BC8: Female | BD8: 20 | BE8: 9 | BF8: A | BG8: Kolkata | BH8: 2023-06-14 | BI8: 84 | BM8: S0019 | BN8: Priya | BO8: Patel | BP8: Female | BQ8: 17 | BR8: 12 | BS8: A | BT8: Chennai | BU8: 2025-04-12 | BV8: 66 | BZ8: S0005 | CA8: Neha | CB8: Kumar | CC8: Female | CD8: 17 | CE8: 10 | CF8: A | CG8: Bengaluru | CH8: 2023-09-21 | CI8: 45 | CM8: S0008 | CN8: Neha | CO8: Paul | CP8: Male | CQ8: 19 | CR8: 12 | CS8: A | CT8: Mumbai | CU8: 2025-01-28 | CV8: 60
A9: S0014 | B9: Sneha | C9: Gupta | D9: Male | E9: 16 | F9: 10 | G9: D | H9: Kolkata | I9: 2023-04-30 | J9: 42 | M9: S0007 | N9: Priya | O9: Roy | P9: Female | Q9: 20 | R9: 9 | S9: C | T9: Hyderabad | U9: 2025-08-17 | V9: 88 | Z9: S0026 | AA9: Priya | AB9: Roy | AC9: Female | AD9: 14 | AE9: 12 | AF9: A | AG9: Delhi | AH9: 2023-11-06 | AI9: 72 | AM9: S0014 | AN9: Sneha | AO9: Gupta | AP9: Male | AQ9: 16 | AR9: 10 | AS9: D | AT9: Kolkata | AU9: 2023-04-30 | AV9: 42 | AZ9: S0007 | BA9: Priya | BB9: Roy | BC9: Female | BD9: 20 | BE9: 9 | BF9: C | BG9: Hyderabad | BH9: 2025-08-17 | BI9: 88 | BM9: S0026 | BN9: Priya | BO9: Roy | BP9: Female | BQ9: 14 | BR9: 12 | BS9: A | BT9: Delhi | BU9: 2023-11-06 | BV9: 72 | BZ9: S0014 | CA9: Sneha | CB9: Gupta | CC9: Male | CD9: 16 | CE9: 10 | CF9: D | CG9: Kolkata | CH9: 2023-04-30 | CI9: 42 | CM9: S0009 | CN9: Amit | CO9: Singh | CP9: Female | CQ9: 19 | CR9: 12 | CS9: B | CT9: Mumbai | CU9: 2023-06-04 | CV9: 92
A10: S0023 | B10: Amit | C10: Paul | D10: Male | E10: 20 | F10: 12 | G10: A | H10: Kolkata | I10: 2024-05-03 | J10: 86 | M10: S0009 | N10: Amit | O10: Singh | P10: Female | Q10: 19 | R10: 12 | S10: B | T10: Mumbai | U10: 2023-06-04 | V10: 92 | Z10: S0029 | AA10: Neha | AB10: Paul | AC10: Female | AD10: 19 | AE10: 12 | AF10: D | AG10: Chennai | AH10: 2024-06-26 | AI10: 54 | AM10: S0023 | AN10: Amit | AO10: Paul | AP10: Male | AQ10: 20 | AR10: 12 | AS10: A | AT10: Kolkata | AU10: 2024-05-03 | AV10: 86 | AZ10: S0009 | BA10: Amit | BB10: Singh | BC10: Female | BD10: 19 | BE10: 12 | BF10: B | BG10: Mumbai | BH10: 2023-06-04 | BI10: 92 | BM10: S0029 | BN10: Neha | BO10: Paul | BP10: Female | BQ10: 19 | BR10: 12 | BS10: D | BT10: Chennai | BU10: 2024-06-26 | BV10: 54 | BZ10: S0019 | CA10: Priya | CB10: Patel | CC10: Female | CD10: 17 | CE10: 12 | CF10: A | CG10: Chennai | CH10: 2025-04-12 | CI10: 66 | CM10: S0013 | CN10: Neha | CO10: Gupta | CP10: Male | CQ10: 15 | CR10: 12 | CS10: B | CT10: Delhi | CU10: 2024-04-25 | CV10: 51
A11: S0030 | B11: Neha | C11: Paul | D11: Male | E11: 20 | F11: 11 | G11: B | H11: Kolkata | I11: 2024-05-26 | J11: 70 | M11: S0010 | N11: Arjun | O11: Roy | P11: Female | Q11: 15 | R11: 9 | S11: C | T11: Pune | U11: 2025-03-19 | V11: 90 | Z11: S0043 | AA11: Sneha | AB11: Roy | AC11: Female | AD11: 17 | AE11: 12 | AF11: A | AG11: Pune | AH11: 2025-05-29 | AI11: 68 | AM11: S0030 | AN11: Neha | AO11: Paul | AP11: Male | AQ11: 20 | AR11: 11 | AS11: B | AT11: Kolkata | AU11: 2024-05-26 | AV11: 70 | AZ11: S0010 | BA11: Arjun | BB11: Roy | BC11: Female | BD11: 15 | BE11: 9 | BF11: C | BG11: Pune | BH11: 2025-03-19 | BI11: 90 | BM11: S0043 | BN11: Sneha | BO11: Roy | BP11: Female | BQ11: 17 | BR11: 12 | BS11: A | BT11: Pune | BU11: 2025-05-29 | BV11: 68 | BZ11: S0022 | CA11: Rahul | CB11: Sharma | CC11: Female | CD11: 16 | CE11: 9 | CF11: C | CG11: Bengaluru | CH11: 2025-02-24 | CI11: 52 | CM11: S0018 | CN11: Pooja | CO11: Patel | CP11: Female | CQ11: 19 | CR11: 9 | CS11: A | CT11: Mumbai | CU11: 2024-05-30 | CV11: 76
A12: S0032 | B12: Arjun | C12: Gupta | D12: Male | E12: 20 | F12: 9 | G12: A | H12: Kolkata | I12: 2023-02-24 | J12: 91 | M12: S0023 | N12: Amit | O12: Paul | P12: Male | Q12: 20 | R12: 12 | S12: A | T12: Kolkata | U12: 2024-05-03 | V12: 86 | Z12: S0050 | AA12: Priya | AB12: Mishra | AC12: Female | AD12: 16 | AE12: 12 | AF12: B | AG12: Bengaluru | AH12: 2024-12-19 | AI12: 85 | AM12: S0032 | AN12: Arjun | AO12: Gupta | AP12: Male | AQ12: 20 | AR12: 9 | AS12: A | AT12: Kolkata | AU12: 2023-02-24 | AV12: 91 | AZ12: S0023 | BA12: Amit | BB12: Paul | BC12: Male | BD12: 20 | BE12: 12 | BF12: A | BG12: Kolkata | BH12: 2024-05-03 | BI12: 86 | BM12: S0050 | BN12: Priya | BO12: Mishra | BP12: Female | BQ12: 16 | BR12: 12 | BS12: B | BT12: Bengaluru | BU12: 2024-12-19 | BV12: 85 | BZ12: S0024 | CA12: Vikram | CB12: Sharma | CC12: Female | CD12: 16 | CE12: 9 | CF12: C | CG12: Jaipur | CH12: 2025-08-25 | CI12: 52 | CM12: S0021 | CN12: Priya | CO12: Patel | CP12: Female | CQ12: 19 | CR12: 9 | CS12: B | CT12: Delhi | CU12: 2025-08-12 | CV12: 50
A13: S0033 | B13: Priya | C13: Mishra | D13: Female | E13: 15 | F13: 11 | G13: C | H13: Kolkata | I13: 2023-03-14 | J13: 77 | M13: S0025 | N13: Pooja | O13: Paul | P13: Male | Q13: 20 | R13: 10 | S13: C | T13: Mumbai | U13: 2025-09-27 | V13: 82 | Z13: S0056 | AA13: Arjun | AB13: Kumar | AC13: Female | AD13: 18 | AE13: 12 | AF13: C | AG13: Chennai | AH13: 2023-12-10 | AI13: 77 | AM13: S0033 | AN13: Priya | AO13: Mishra | AP13: Female | AQ13: 15 | AR13: 11 | AS13: C | AT13: Kolkata | AU13: 2023-03-14 | AV13: 77 | AZ13: S0025 | BA13: Pooja | BB13: Paul | BC13: Male | BD13: 20 | BE13: 10 | BF13: C | BG13: Mumbai | BH13: 2025-09-27 | BI13: 82 | BM13: S0056 | BN13: Arjun | BO13: Kumar | BP13: Female | BQ13: 18 | BR13: 12 | BS13: C | BT13: Chennai | BU13: 2023-12-10 | BV13: 77 | BZ13: S0031 | CA13: Priya | CB13: Ghosh | CC13: Female | CD13: 18 | CE13: 10 | CF13: D | CG13: Delhi | CH13: 2024-12-14 | CI13: 57 | CM13: S0025 | CN13: Pooja | CO13: Paul | CP13: Male | CQ13: 20 | CR13: 10 | CS13: C | CT13: Mumbai | CU13: 2025-09-27 | CV13: 82
A14: S0035 | B14: Pooja | C14: Singh | D14: Male | E14: 15 | F14: 9 | G14: B | H14: Kolkata | I14: 2025-03-27 | J14: 58 | M14: S0032 | N14: Arjun | O14: Gupta | P14: Male | Q14: 20 | R14: 9 | S14: A | T14: Kolkata | U14: 2023-02-24 | V14: 91 | Z14: S0068 | AA14: Priya | AB14: Patel | AC14: Female | AD14: 19 | AE14: 12 | AF14: C | AG14: Delhi | AH14: 2025-07-15 | AI14: 99 | AM14: S0035 | AN14: Pooja | AO14: Singh | AP14: Male | AQ14: 15 | AR14: 9 | AS14: B | AT14: Kolkata | AU14: 2025-03-27 | AV14: 58 | AZ14: S0032 | BA14: Arjun | BB14: Gupta | BC14: Male | BD14: 20 | BE14: 9 | BF14: A | BG14: Kolkata | BH14: 2023-02-24 | BI14: 91 | BM14: S0068 | BN14: Priya | BO14: Patel | BP14: Female | BQ14: 19 | BR14: 12 | BS14: C | BT14: Delhi | BU14: 2025-07-15 | BV14: 99 | BZ14: S0041 | CA14: Vikram | CB14: Kumar | CC14: Male | CD14: 18 | CE14: 10 | CF14: C | CG14: Jaipur | CH14: 2024-05-20 | CI14: 66 | CM14: S0026 | CN14: Priya | CO14: Roy | CP14: Female | CQ14: 14 | CR14: 12 | CS14: A | CT14: Delhi | CU14: 2023-11-06 | CV14: 72
A15: S0038 | B15: Rahul | C15: Patel | D15: Female | E15: 20 | F15: 10 | G15: A | H15: Kolkata | I15: 2023-09-23 | J15: 52 | M15: S0044 | N15: Pooja | O15: Singh | P15: Male | Q15: 17 | R15: 12 | S15: D | T15: Hyderabad | U15: 2025-09-16 | V15: 82 | Z15: S0071 | AA15: Sneha | AB15: Singh | AC15: Female | AD15: 17 | AE15: 12 | AF15: B | AG15: Bengaluru | AH15: 2024-01-25 | AI15: 49 | AM15: S0038 | AN15: Rahul | AO15: Patel | AP15: Female | AQ15: 20 | AR15: 10 | AS15: A | AT15: Kolkata | AU15: 2023-09-23 | AV15: 52 | AZ15: S0044 | BA15: Pooja | BB15: Singh | BC15: Male | BD15: 17 | BE15: 12 | BF15: D | BG15: Hyderabad | BH15: 2025-09-16 | BI15: 82 | BM15: S0071 | BN15: Sneha | BO15: Singh | BP15: Female | BQ15: 17 | BR15: 12 | BS15: B | BT15: Bengaluru | BU15: 2024-01-25 | BV15: 49 | BZ15: S0043 | CA15: Sneha | CB15: Roy | CC15: Female | CD15: 17 | CE15: 12 | CF15: A | CG15: Pune | CH15: 2025-05-29 | CI15: 68 | CM15: S0031 | CN15: Priya | CO15: Ghosh | CP15: Female | CQ15: 18 | CR15: 10 | CS15: D | CT15: Delhi | CU15: 2024-12-14 | CV15: 57
A16: S0051 | B16: Pooja | C16: Paul | D16: Female | E16: 20 | F16: 10 | G16: B | H16: Kolkata | I16: 2025-07-27 | J16: 71 | M16: S0045 | N16: Priya | O16: Paul | P16: Male | Q16: 17 | R16: 10 | S16: D | T16: Bengaluru | U16: 2023-04-05 | V16: 88 | Z16: S0072 | AA16: Neha | AB16: Singh | AC16: Female | AD16: 14 | AE16: 12 | AF16: C | AG16: Delhi | AH16: 2025-08-28 | AI16: 45 | AM16: S0051 | AN16: Pooja | AO16: Paul | AP16: Female | AQ16: 20 | AR16: 10 | AS16: B | AT16: Kolkata | AU16: 2025-07-27 | AV16: 71 | AZ16: S0045 | BA16: Priya | BB16: Paul | BC16: Male | BD16: 17 | BE16: 10 | BF16: D | BG16: Bengaluru | BH16: 2023-04-05 | BI16: 88 | BM16: S0072 | BN16: Neha | BO16: Singh | BP16: Female | BQ16: 14 | BR16: 12 | BS16: C | BT16: Delhi | BU16: 2025-08-28 | BV16: 45 | BZ16: S0044 | CA16: Pooja | CB16: Singh | CC16: Male | CD16: 17 | CE16: 12 | CF16: D | CG16: Hyderabad | CH16: 2025-09-16 | CI16: 82 | CM16: S0036 | CN16: Pooja | CO16: Patel | CP16: Male | CQ16: 20 | CR16: 9 | CS16: D | CT16: Mumbai | CU16: 2024-09-17 | CV16: 40
A17: S0063 | B17: Amit | C17: Ghosh | D17: Male | E17: 17 | F17: 12 | G17: D | H17: Kolkata | I17: 2024-09-04 | J17: 82 | M17: S0048 | N17: Arjun | O17: Sharma | P17: Male | Q17: 18 | R17: 11 | S17: C | T17: Delhi | U17: 2024-08-25 | V17: 100 | Z17: S0075 | AA17: Amit | AB17: Das | AC17: Female | AD17: 14 | AE17: 12 | AF17: A | AG17: Bengaluru | AH17: 2025-02-17 | AI17: 63 | AM17: S0063 | AN17: Amit | AO17: Ghosh | AP17: Male | AQ17: 17 | AR17: 12 | AS17: D | AT17: Kolkata | AU17: 2024-09-04 | AV17: 82 | AZ17: S0048 | BA17: Arjun | BB17: Sharma | BC17: Male | BD17: 18 | BE17: 11 | BF17: C | BG17: Delhi | BH17: 2024-08-25 | BI17: 100 | BM17: S0075 | BN17: Amit | BO17: Das | BP17: Female | BQ17: 14 | BR17: 12 | BS17: A | BT17: Bengaluru | BU17: 2025-02-17 | BV17: 63 | BZ17: S0045 | CA17: Priya | CB17: Paul | CC17: Male | CD17: 17 | CE17: 10 | CF17: D | CG17: Bengaluru | CH17: 2023-04-05 | CI17: 88 | CM17: S0039 | CN17: Neha | CO17: Kumar | CP17: Female | CQ17: 20 | CR17: 10 | CS17: C | CT17: Delhi | CU17: 2023-12-22 | CV17: 37
A18: S0069 | B18: Priya | C18: Patel | D18: Female | E18: 16 | F18: 11 | G18: D | H18: Kolkata | I18: 2023-07-19 | J18: 75 | M18: S0049 | N18: Neha | O18: Singh | P18: Female | Q18: 19 | R18: 10 | S18: A | T18: Chennai | U18: 2023-04-24 | V18: 93 | Z18: S0088 | AA18: Rahul | AB18: Kumar | AC18: Female | AD18: 19 | AE18: 12 | AF18: B | AG18: Bengaluru | AH18: 2023-06-28 | AI18: 84 | AM18: S0069 | AN18: Priya | AO18: Patel | AP18: Female | AQ18: 16 | AR18: 11 | AS18: D | AT18: Kolkata | AU18: 2023-07-19 | AV18: 75 | AZ18: S0049 | BA18: Neha | BB18: Singh | BC18: Female | BD18: 19 | BE18: 10 | BF18: A | BG18: Chennai | BH18: 2023-04-24 | BI18: 93 | BM18: S0088 | BN18: Rahul | BO18: Kumar | BP18: Female | BQ18: 19 | BR18: 12 | BS18: B | BT18: Bengaluru | BU18: 2023-06-28 | BV18: 84 | BZ18: S0048 | CA18: Arjun | CB18: Sharma | CC18: Male | CD18: 18 | CE18: 11 | CF18: C | CG18: Delhi | CH18: 2024-08-25 | CI18: 100 | CM18: S0047 | CN18: Sneha | CO18: Ghosh | CP18: Male | CQ18: 14 | CR18: 10 | CS18: C | CT18: Delhi | CU18: 2024-09-04 | CV18: 65
A19: S0080 | B19: Priya | C19: Paul | D19: Male | E19: 18 | F19: 12 | G19: D | H19: Kolkata | I19: 2025-06-29 | J19: 89 | M19: S0050 | N19: Priya | O19: Mishra | P19: Female | Q19: 16 | R19: 12 | S19: B | T19: Bengaluru | U19: 2024-12-19 | V19: 85 | Z19: S0098 | AA19: Sneha | AB19: Kumar | AC19: Female | AD19: 14 | AE19: 12 | AF19: C | AG19: Hyderabad | AH19: 2024-04-17 | AI19: 65 | AM19: S0080 | AN19: Priya | AO19: Paul | AP19: Male | AQ19: 18 | AR19: 12 | AS19: D | AT19: Kolkata | AU19: 2025-06-29 | AV19: 89 | AZ19: S0050 | BA19: Priya | BB19: Mishra | BC19: Female | BD19: 16 | BE19: 12 | BF19: B | BG19: Bengaluru | BH19: 2024-12-19 | BI19: 85 | BM19: S0098 | BN19: Sneha | BO19: Kumar | BP19: Female | BQ19: 14 | BR19: 12 | BS19: C | BT19: Hyderabad | BU19: 2024-04-17 | BV19: 65 | BZ19: S0050 | CA19: Priya | CB19: Mishra | CC19: Female | CD19: 16 | CE19: 12 | CF19: B | CG19: Bengaluru | CH19: 2024-12-19 | CI19: 85 | CM19: S0048 | CN19: Arjun | CO19: Sharma | CP19: Male | CQ19: 18 | CR19: 11 | CS19: C | CT19: Delhi | CU19: 2024-08-25 | CV19: 100
... A63: S0499 | B63: Amit | C63: Patel | D63: Male | E63: 16 | F63: 12 | G63: D | H63: Kolkata | I63: 2025-06-05 | J63: 41 | M63: S0217 | N63: Sneha | O63: Gupta | P63: Male | Q63: 15 | R63: 9 | S63: A | T63: Delhi | U63: 2023-06-17 | V63: 97 | Z63: S0360 | AA63: Rahul | AB63: Gupta | AC63: Female | AD63: 14 | AE63: 12 | AF63: C | AG63: Chennai | AH63: 2023-07-22 | AI63: 63 | AM63: S0499 | AN63: Amit | AO63: Patel | AP63: Male | AQ63: 16 | AR63: 12 | AS63: D | AT63: Kolkata | AU63: 2025-06-05 | AV63: 41 | AZ63: S0217 | BA63: Sneha | BB63: Gupta | BC63: Male | BD63: 15 | BE63: 9 | BF63: A | BG63: Delhi | BH63: 2023-06-17 | BI63: 97 | BM63: S0360 | BN63: Rahul | BO63: Gupta | BP63: Female | BQ63: 14 | BR63: 12 | BS63: C | BT63: Chennai | BU63: 2023-07-22 | BV63: 63 | BZ63: S0150 | CA63: Pooja | CB63: Paul | CC63: Female | CD63: 18 | CE63: 11 | CF63: A | CG63: Chennai | CH63: 2024-12-30 | CI63: 97 | CM63: S0186 | CN63: Sneha | CO63: Paul | CP63: Female | CQ63: 19 | CR63: 9 | CS63: C | CT63: Mumbai | CU63: 2023-06-22 | CV63: 37
M64: S0218 | N64: Sneha | O64: Gupta | P64: Male | Q64: 19 | R64: 11 | S64: B | T64: Mumbai | U64: 2024-01-29 | V64: 81 | Z64: S0361 | AA64: Vikram | AB64: Mishra | AC64: Female | AD64: 20 | AE64: 12 | AF64: C | AG64: Bengaluru | AH64: 2023-01-11 | AI64: 35 | AZ64: S0218 | BA64: Sneha | BB64: Gupta | BC64: Male | BD64: 19 | BE64: 11 | BF64: B | BG64: Mumbai | BH64: 2024-01-29 | BI64: 81 | BM64: S0361 | BN64: Vikram | BO64: Mishra | BP64: Female | BQ64: 20 | BR64: 12 | BS64: C | BT64: Bengaluru | BU64: 2023-01-11 | BV64: 35 | BZ64: S0153 | CA64: Karan | CB64: Kumar | CC64: Male | CD64: 18 | CE64: 9 | CF64: A | CG64: Bengaluru | CH64: 2023-07-26 | CI64: 64 | CM64: S0189 | CN64: Arjun | CO64: Sharma | CP64: Male | CQ64: 17 | CR64: 11 | CS64: D | CT64: Mumbai | CU64: 2025-03-19 | CV64: 42
M65: S0228 | N65: Priya | O65: Gupta | P65: Male | Q65: 19 | R65: 10 | S65: C | T65: Kolkata | U65: 2025-09-24 | V65: 88 | Z65: S0364 | AA65: Priya | AB65: Roy | AC65: Female | AD65: 16 | AE65: 12 | AF65: A | AG65: Kolkata | AH65: 2024-03-08 | AI65: 57 | AZ65: S0228 | BA65: Priya | BB65: Gupta | BC65: Male | BD65: 19 | BE65: 10 | BF65: C | BG65: Kolkata | BH65: 2025-09-24 | BI65: 88 | BM65: S0364 | BN65: Priya | BO65: Roy | BP65: Female | BQ65: 16 | BR65: 12 | BS65: A | BT65: Kolkata | BU65: 2024-03-08 | BV65: 57 | BZ65: S0158 | CA65: Neha | CB65: Singh | CC65: Female | CD65: 18 | CE65: 12 | CF65: C | CG65: Bengaluru | CH65: 2024-07-17 | CI65: 53 | CM65: S0190 | CN65: Rahul | CO65: Roy | CP65: Male | CQ65: 20 | CR65: 9 | CS65: D | CT65: Mumbai | CU65: 2024-01-06 | CV65: 68
M66: S0231 | N66: Neha | O66: Roy | P66: Male | Q66: 18 | R66: 11 | S66: B | T66: Delhi | U66: 2025-07-01 | V66: 86 | Z66: S0370 | AA66: Vikram | AB66: Ghosh | AC66: Female | AD66: 19 | AE66: 12 | AF66: D | AG66: Hyderabad | AH66: 2025-03-17 | AI66: 65 | AZ66: S0231 | BA66: Neha | BB66: Roy | BC66: Male | BD66: 18 | BE66: 11 | BF66: B | BG66: Delhi | BH66: 2025-07-01 | BI66: 86 | BM66: S0370 | BN66: Vikram | BO66: Ghosh | BP66: Female | BQ66: 19 | BR66: 12 | BS66: D | BT66: Hyderabad | BU66: 2025-03-17 | BV66: 65 | BZ66: S0162 | CA66: Karan | CB66: Roy | CC66: Male | CD66: 16 | CE66: 9 | CF66: D | CG66: Jaipur | CH66: 2024-12-06 | CI66: 66 | CM66: S0192 | CN66: Pooja | CO66: Gupta | CP66: Male | CQ66: 16 | CR66: 12 | CS66: A | CT66: Mumbai | CU66: 2023-11-16 | CV66: 85
M67: S0234 | N67: Amit | O67: Ghosh | P67: Male | Q67: 16 | R67: 11 | S67: C | T67: Delhi | U67: 2024-03-14 | V67: 86 | Z67: S0375 | AA67: Rahul | AB67: Sharma | AC67: Female | AD67: 17 | AE67: 12 | AF67: C | AG67: Pune | AH67: 2023-07-09 | AI67: 77 | AZ67: S0234 | BA67: Amit | BB67: Ghosh | BC67: Male | BD67: 16 | BE67: 11 | BF67: C | BG67: Delhi | BH67: 2024-03-14 | BI67: 86 | BM67: S0375 | BN67: Rahul | BO67: Sharma | BP67: Female | BQ67: 17 | BR67: 12 | BS67: C | BT67: Pune | BU67: 2023-07-09 | BV67: 77 | BZ67: S0166 | CA67: Sneha | CB67: Gupta | CC67: Male | CD67: 16 | CE67: 10 | CF67: A | CG67: Pune | CH67: 2024-08-16 | CI67: 72 | CM67: S0196 | CN67: Pooja | CO67: Sharma | CP67: Male | CQ67: 16 | CR67: 11 | CS67: C | CT67: Mumbai | CU67: 2023-02-12 | CV67: 55
M68: S0235 | N68: Vikram | O68: Patel | P68: Female | Q68: 20 | R68: 10 | S68: A | T68: Jaipur | U68: 2025-05-08 | V68: 93 | Z68: S0376 | AA68: Vikram | AB68: Roy | AC68: Female | AD68: 16 | AE68: 12 | AF68: C | AG68: Kolkata | AH68: 2023-09-25 | AI68: 85 | AZ68: S0235 | BA68: Vikram | BB68: Patel | BC68: Female | BD68: 20 | BE68: 10 | BF68: A | BG68: Jaipur | BH68: 2025-05-08 | BI68: 93 | BM68: S0376 | BN68: Vikram | BO68: Roy | BP68: Female | BQ68: 16 | BR68: 12 | BS68: C | BT68: Kolkata | BU68: 2023-09-25 | BV68: 85 | BZ68: S0168 | CA68: Karan | CB68: Roy | CC68: Female | CD68: 17 | CE68: 12 | CF68: C | CG68: Delhi | CH68: 2025-05-08 | CI68: 96 | CM68: S0210 | CN68: Riya | CO68: Mishra | CP68: Male | CQ68: 20 | CR68: 10 | CS68: A | CT68: Mumbai | CU68: 2024-07-07 | CV68: 85
M69: S0248 | N69: Neha | O69: Das | P69: Female | Q69: 15 | R69: 9 | S69: D | T69: Pune | U69: 2025-02-18 | V69: 95 | Z69: S0384 | AA69: Pooja | AB69: Ghosh | AC69: Female | AD69: 20 | AE69: 12 | AF69: D | AG69: Chennai | AH69: 2025-07-09 | AI69: 91 | AZ69: S0248 | BA69: Neha | BB69: Das | BC69: Female | BD69: 15 | BE69: 9 | BF69: D | BG69: Pune | BH69: 2025-02-18 | BI69: 95 | BM69: S0384 | BN69: Pooja | BO69: Ghosh | BP69: Female | BQ69: 20 | BR69: 12 | BS69: D | BT69: Chennai | BU69: 2025-07-09 | BV69: 91 | BZ69: S0171 | CA69: Neha | CB69: Kumar | CC69: Male | CD69: 18 | CE69: 11 | CF69: D | CG69: Hyderabad | CH69: 2023-08-15 | CI69: 62 | CM69: S0215 | CN69: Priya | CO69: Paul | CP69: Female | CQ69: 16 | CR69: 11 | CS69: C | CT69: Delhi | CU69: 2024-07-27 | CV69: 40
M70: S0251 | N70: Amit | O70: Mishra | P70: Female | Q70: 14 | R70: 11 | S70: A | T70: Mumbai | U70: 2025-09-25 | V70: 86 | Z70: S0390 | AA70: Vikram | AB70: Sharma | AC70: Female | AD70: 20 | AE70: 12 | AF70: C | AG70: Jaipur | AH70: 2023-05-06 | AI70: 82 | AZ70: S0251 | BA70: Amit | BB70: Mishra | BC70: Female | BD70: 14 | BE70: 11 | BF70: A | BG70: Mumbai | BH70: 2025-09-25 | BI70: 86 | BM70: S0390 | BN70: Vikram | BO70: Sharma | BP70: Female | BQ70: 20 | BR70: 12 | BS70: C | BT70: Jaipur | BU70: 2023-05-06 | BV70: 82 | BZ70: S0173 | CA70: Amit | CB70: Gupta | CC70: Female | CD70: 17 | CE70: 9 | CF70: A | CG70: Kolkata | CH70: 2023-12-12 | CI70: 66 | CM70: S0216 | CN70: Priya | CO70: Singh | CP70: Male | CQ70: 16 | CR70: 9 | CS70: B | CT70: Delhi | CU70: 2024-01-22 | CV70: 60
M71: S0254 | N71: Riya | O71: Ghosh | P71: Female | Q71: 18 | R71: 10 | S71: B | T71: Delhi | U71: 2023-12-29 | V71: 82 | Z71: S0412 | AA71: Riya | AB71: Kumar | AC71: Female | AD71: 17 | AE71: 12 | AF71: B | AG71: Mumbai | AH71: 2025-02-28 | AI71: 59 | AZ71: S0254 | BA71: Riya | BB71: Ghosh | BC71: Female | BD71: 18 | BE71: 10 | BF71: B | BG71: Delhi | BH71: 2023-12-29 | BI71: 82 | BM71: S0412 | BN71: Riya | BO71: Kumar | BP71: Female | BQ71: 17 | BR71: 12 | BS71: B | BT71: Mumbai | BU71: 2025-02-28 | BV71: 59 | BZ71: S0174 | CA71: Sneha | CB71: Roy | CC71: Female | CD71: 18 | CE71: 11 | CF71: A | CG71: Delhi | CH71: 2023-12-28 | CI71: 67 | CM71: S0217 | CN71: Sneha | CO71: Gupta | CP71: Male | CQ71: 15 | CR71: 9 | CS71: A | CT71: Delhi | CU71: 2023-06-17 | CV71: 97
M72: S0255 | N72: Neha | O72: Sharma | P72: Male | Q72: 20 | R72: 10 | S72: B | T72: Hyderabad | U72: 2025-09-14 | V72: 92 | Z72: S0428 | AA72: Sneha | AB72: Ghosh | AC72: Female | AD72: 18 | AE72: 12 | AF72: C | AG72: Bengaluru | AH72: 2023-08-29 | AI72: 94 | AZ72: S0255 | BA72: Neha | BB72: Sharma | BC72: Male | BD72: 20 | BE72: 10 | BF72: B | BG72: Hyderabad | BH72: 2025-09-14 | BI72: 92 | BM72: S0428 | BN72: Sneha | BO72: Ghosh | BP72: Female | BQ72: 18 | BR72: 12 | BS72: C | BT72: Bengaluru | BU72: 2023-08-29 | BV72: 94 | BZ72: S0175 | CA72: Arjun | CB72: Sharma | CC72: Male | CD72: 16 | CE72: 10 | CF72: C | CG72: Delhi | CH72: 2024-10-03 | CI72: 72 | CM72: S0218 | CN72: Sneha | CO72: Gupta | CP72: Male | CQ72: 19 | CR72: 11 | CS72: B | CT72: Mumbai | CU72: 2024-01-29 | CV72: 81
M73: S0257 | N73: Sneha | O73: Sharma | P73: Male | Q73: 20 | R73: 12 | S73: D | T73: Mumbai | U73: 2023-05-23 | V73: 86 | Z73: S0458 | AA73: Amit | AB73: Ghosh | AC73: Female | AD73: 19 | AE73: 12 | AF73: A | AG73: Chennai | AH73: 2024-02-15 | AI73: 83 | AZ73: S0257 | BA73: Sneha | BB73: Sharma | BC73: Male | BD73: 20 | BE73: 12 | BF73: D | BG73: Mumbai | BH73: 2023-05-23 | BI73: 86 | BM73: S0458 | BN73: Amit | BO73: Ghosh | BP73: Female | BQ73: 19 | BR73: 12 | BS73: A | BT73: Chennai | BU73: 2024-02-15 | BV73: 83 | BZ73: S0176 | CA73: Riya | CB73: Das | CC73: Female | CD73: 16 | CE73: 12 | CF73: D | CG73: Jaipur | CH73: 2024-07-27 | CI73: 39 | CM73: S0224 | CN73: Neha | CO73: Mishra | CP73: Female | CQ73: 16 | CR73: 11 | CS73: A | CT73: Delhi | CU73: 2025-08-11 | CV73: 65
M74: S0262 | N74: Arjun | O74: Das | P74: Female | Q74: 14 | R74: 11 | S74: C | T74: Jaipur | U74: 2025-02-28 | V74: 93 | Z74: S0463 | AA74: Pooja | AB74: Roy | AC74: Female | AD74: 14 | AE74: 12 | AF74: D | AG74: Mumbai | AH74: 2024-05-23 | AI74: 58 | AZ74: S0262 | BA74: Arjun | BB74: Das | BC74: Female | BD74: 14 | BE74: 11 | BF74: C | BG74: Jaipur | BH74: 2025-02-28 | BI74: 93 | BM74: S0463 | BN74: Pooja | BO74: Roy | BP74: Female | BQ74: 14 | BR74: 12 | BS74: D | BT74: Mumbai | BU74: 2024-05-23 | BV74: 58 | BZ74: S0177 | CA74: Vikram | CB74: Mishra | CC74: Male | CD74: 18 | CE74: 9 | CF74: D | CG74: Mumbai | CH74: 2023-12-07 | CI74: 74 | CM74: S0226 | CN74: Amit | CO74: Das | CP74: Female | CQ74: 16 | CR74: 11 | CS74: B | CT74: Delhi | CU74: 2024-05-19 | CV74: 75
M75: S0270 | N75: Arjun | O75: Kumar | P75: Female | Q75: 14 | R75: 9 | S75: B | T75: Mumbai | U75: 2025-02-08 | V75: 81 | Z75: S0468 | AA75: Vikram | AB75: Das | AC75: Female | AD75: 18 | AE75: 12 | AF75: A | AG75: Mumbai | AH75: 2023-04-25 | AI75: 88 | AZ75: S0270 | BA75: Arjun | BB75: Kumar | BC75: Female | BD75: 14 | BE75: 9 | BF75: B | BG75: Mumbai | BH75: 2025-02-08 | BI75: 81 | BM75: S0468 | BN75: Vikram | BO75: Das | BP75: Female | BQ75: 18 | BR75: 12 | BS75: A | BT75: Mumbai | BU75: 2023-04-25 | BV75: 88 | BZ75: S0182 | CA75: Sneha | CB75: Mishra | CC75: Male | CD75: 18 | CE75: 11 | CF75: D | CG75: Bengaluru | CH75: 2023-10-27 | CI75: 65 | CM75: S0231 | CN75: Neha | CO75: Roy | CP75: Male | CQ75: 18 | CR75: 11 | CS75: B | CT75: Delhi | CU75: 2025-07-01 | CV75: 86
... M78: S0273 | N78: Neha | O78: Singh | P78: Male | Q78: 19 | R78: 11 | S78: B | T78: Chennai | U78: 2023-09-15 | V78: 81 | Z78: S0488 | AA78: Vikram | AB78: Gupta | AC78: Female | AD78: 16 | AE78: 12 | AF78: C | AG78: Bengaluru | AH78: 2023-06-21 | AI78: 77 | AZ78: S0273 | BA78: Neha | BB78: Singh | BC78: Male | BD78: 19 | BE78: 11 | BF78: B | BG78: Chennai | BH78: 2023-09-15 | BI78: 81 | BM78: S0488 | BN78: Vikram | BO78: Gupta | BP78: Female | BQ78: 16 | BR78: 12 | BS78: C | BT78: Bengaluru | BU78: 2023-06-21 | BV78: 77 | BZ78: S0188 | CA78: Priya | CB78: Paul | CC78: Female | CD78: 16 | CE78: 10 | CF78: B | CG78: Hyderabad | CH78: 2023-09-19 | CI78: 100 | CM78: S0241 | CN78: Riya | CO78: Das | CP78: Female | CQ78: 20 | CR78: 9 | CS78: A | CT78: Mumbai | CU78: 2023-07-02 | CV78: 42
M79: S0275 | N79: Pooja | O79: Gupta | P79: Female | Q79: 16 | R79: 9 | S79: B | T79: Chennai | U79: 2024-06-05 | V79: 93 | AZ79: S0275 | BA79: Pooja | BB79: Gupta | BC79: Female | BD79: 16 | BE79: 9 | BF79: B | BG79: Chennai | BH79: 2024-06-05 | BI79: 93 | BZ79: S0189 | CA79: Arjun | CB79: Sharma | CC79: Male | CD79: 17 | CE79: 11 | CF79: D | CG79: Mumbai | CH79: 2025-03-19 | CI79: 42 | CM79: S0242 | CN79: Rahul | CO79: Das | CP79: Male | CQ79: 18 | CR79: 10 | CS79: B | CT79: Delhi | CU79: 2023-02-19 | CV79: 76
M80: S0282 | N80: Riya | O80: Paul | P80: Female | Q80: 18 | R80: 12 | S80: D | T80: Kolkata | U80: 2024-08-01 | V80: 96 | AZ80: S0282 | BA80: Riya | BB80: Paul | BC80: Female | BD80: 18 | BE80: 12 | BF80: D | BG80: Kolkata | BH80: 2024-08-01 | BI80: 96 | BZ80: S0192 | CA80: Pooja | CB80: Gupta | CC80: Male | CD80: 16 | CE80: 12 | CF80: A | CG80: Mumbai | CH80: 2023-11-16 | CI80: 85 | CM80: S0243 | CN80: Rahul | CO80: Das | CP80: Female | CQ80: 15 | CR80: 10 | CS80: C | CT80: Delhi | CU80: 2024-01-07 | CV80: 44
M81: S0283 | N81: Riya | O81: Paul | P81: Female | Q81: 17 | R81: 9 | S81: D | T81: Bengaluru | U81: 2024-09-06 | V81: 100 | AZ81: S0283 | BA81: Riya | BB81: Paul | BC81: Female | BD81: 17 | BE81: 9 | BF81: D | BG81: Bengaluru | BH81: 2024-09-06 | BI81: 100 | BZ81: S0193 | CA81: Sneha | CB81: Gupta | CC81: Male | CD81: 16 | CE81: 12 | CF81: A | CG81: Bengaluru | CH81: 2025-02-22 | CI81: 47 | CM81: S0245 | CN81: Riya | CO81: Paul | CP81: Female | CQ81: 16 | CR81: 12 | CS81: C | CT81: Delhi | CU81: 2025-07-01 | CV81: 45
M82: S0286 | N82: Riya | O82: Roy | P82: Male | Q82: 19 | R82: 9 | S82: C | T82: Mumbai | U82: 2023-12-03 | V82: 94 | AZ82: S0286 | BA82: Riya | BB82: Roy | BC82: Male | BD82: 19 | BE82: 9 | BF82: C | BG82: Mumbai | BH82: 2023-12-03 | BI82: 94 | BZ82: S0196 | CA82: Pooja | CB82: Sharma | CC82: Male | CD82: 16 | CE82: 11 | CF82: C | CG82: Mumbai | CH82: 2023-02-12 | CI82: 55 | CM82: S0246 | CN82: Pooja | CO82: Gupta | CP82: Male | CQ82: 15 | CR82: 11 | CS82: C | CT82: Mumbai | CU82: 2023-01-31 | CV82: 54
M83: S0296 | N83: Arjun | O83: Das | P83: Female | Q83: 18 | R83: 10 | S83: C | T83: Chennai | U83: 2023-01-01 | V83: 98 | AZ83: S0296 | BA83: Arjun | BB83: Das | BC83: Female | BD83: 18 | BE83: 10 | BF83: C | BG83: Chennai | BH83: 2023-01-01 | BI83: 98 | BZ83: S0198 | CA83: Priya | CB83: Kumar | CC83: Female | CD83: 16 | CE83: 12 | CF83: A | CG83: Bengaluru | CH83: 2023-07-19 | CI83: 89 | CM83: S0251 | CN83: Amit | CO83: Mishra | CP83: Female | CQ83: 14 | CR83: 11 | CS83: A | CT83: Mumbai | CU83: 2025-09-25 | CV83: 86
M84: S0297 | N84: Riya | O84: Gupta | P84: Male | Q84: 20 | R84: 11 | S84: C | T84: Hyderabad | U84: 2024-09-21 | V84: 84 | AZ84: S0297 | BA84: Riya | BB84: Gupta | BC84: Male | BD84: 20 | BE84: 11 | BF84: C | BG84: Hyderabad | BH84: 2024-09-21 | BI84: 84 | BZ84: S0200 | CA84: Riya | CB84: Mishra | CC84: Female | CD84: 16 | CE84: 12 | CF84: D | CG84: Jaipur | CH84: 2025-09-07 | CI84: 82 | CM84: S0252 | CN84: Arjun | CO84: Mishra | CP84: Female | CQ84: 17 | CR84: 11 | CS84: D | CT84: Delhi | CU84: 2023-05-17 | CV84: 52
M85: S0304 | N85: Riya | O85: Das | P85: Female | Q85: 20 | R85: 10 | S85: C | T85: Bengaluru | U85: 2024-11-28 | V85: 99 | AZ85: S0304 | BA85: Riya | BB85: Das | BC85: Female | BD85: 20 | BE85: 10 | BF85: C | BG85: Bengaluru | BH85: 2024-11-28 | BI85: 99 | BZ85: S0201 | CA85: Riya | CB85: Gupta | CC85: Male | CD85: 16 | CE85: 11 | CF85: D | CG85: Pune | CH85: 2025-09-22 | CI85: 86 | CM85: S0254 | CN85: Riya | CO85: Ghosh | CP85: Female | CQ85: 18 | CR85: 10 | CS85: B | CT85: Delhi | CU85: 2023-12-29 | CV85: 82
M86: S0306 | N86: Vikram | O86: Patel | P86: Male | Q86: 14 | R86: 10 | S86: D | T86: Bengaluru | U86: 2024-07-11 | V86: 90 | AZ86: S0306 | BA86: Vikram | BB86: Patel | BC86: Male | BD86: 14 | BE86: 10 | BF86: D | BG86: Bengaluru | BH86: 2024-07-11 | BI86: 90 | BZ86: S0202 | CA86: Riya | CB86: Singh | CC86: Male | CD86: 18 | CE86: 11 | CF86: D | CG86: Kolkata | CH86: 2024-08-14 | CI86: 91 | CM86: S0257 | CN86: Sneha | CO86: Sharma | CP86: Male | CQ86: 20 | CR86: 12 | CS86: D | CT86: Mumbai | CU86: 2023-05-23 | CV86: 86
...

Sheet conditional_format
A1: 11. Highlight marks greater than 90. | N1: 13. Apply color scales to Marks.
A2: 12. Highlight marks below 40. | N2: 15. Highlight students aged above 18.
A4: 14. Highlight duplicate First Names. | O4: Student_ID | P4: First_Name | Q4: Last_Name | R4: Gender | S4: Age | T4: Class | U4: Section | V4: City | W4: Admission_Date | X4: Marks
O5: S0001 | P5: Sneha | Q5: Paul | R5: Male | S5: 16 | T5: 10 | U5: B | V5: Pune | W5: 2024-10-06 | X5: 37
O6: S0002 | P6: Amit | Q6: Das | R6: Male | S6: 15 | T6: 12 | U6: B | V6: Jaipur | W6: 2024-11-06 | X6: 98
A7: Student_ID | B7: First_Name | C7: Last_Name | D7: Gender | E7: Age | F7: Class | G7: Section | H7: City | I7: Admission_Date | J7: Marks | L7: Sneha | O7: S0003 | P7: Karan | Q7: Roy | R7: Male | S7: 14 | T7: 12 | U7: D | V7: Kolkata | W7: 2024-10-12 | X7: 38
A8: S0001 | B8: Sneha | C8: Paul | D8: Male | E8: 16 | F8: 10 | G8: B | H8: Pune | I8: 2024-10-06 | J8: 37 | L8: Amit | O8: S0004 | P8: Priya | Q8: Singh | R8: Female | S8: 20 | T8: 9 | U8: A | V8: Kolkata | W8: 2023-06-14 | X8: 84
A9: S0002 | B9: Amit | C9: Das | D9: Male | E9: 15 | F9: 12 | G9: B | H9: Jaipur | I9: 2024-11-06 | J9: 98 | L9: Karan | O9: S0005 | P9: Neha | Q9: Kumar | R9: Female | S9: 17 | T9: 10 | U9: A | V9: Bengaluru | W9: 2023-09-21 | X9: 45
A10: S0003 | B10: Karan | C10: Roy | D10: Male | E10: 14 | F10: 12 | G10: D | H10: Kolkata | I10: 2024-10-12 | J10: 38 | L10: Priya | O10: S0006 | P10: Sneha | Q10: Paul | R10: Female | S10: 19 | T10: 10 | U10: B | V10: Hyderabad | W10: 2023-09-12 | X10: 36
A11: S0004 | B11: Priya | C11: Singh | D11: Female | E11: 20 | F11: 9 | G11: A | H11: Kolkata | I11: 2023-06-14 | J11: 84 | L11: Neha | O11: S0007 | P11: Priya | Q11: Roy | R11: Female | S11: 20 | T11: 9 | U11: C | V11: Hyderabad | W11: 2025-08-17 | X11: 88
A12: S0005 | B12: Neha | C12: Kumar | D12: Female | E12: 17 | F12: 10 | G12: A | H12: Bengaluru | I12: 2023-09-21 | J12: 45 | L12: Arjun | O12: S0008 | P12: Neha | Q12: Paul | R12: Male | S12: 19 | T12: 12 | U12: A | V12: Mumbai | W12: 2025-01-28 | X12: 60
A13: S0006 | B13: Sneha | C13: Paul | D13: Female | E13: 19 | F13: 10 | G13: B | H13: Hyderabad | I13: 2023-09-12 | J13: 36 | L13: Riya | O13: S0009 | P13: Amit | Q13: Singh | R13: Female | S13: 19 | T13: 12 | U13: B | V13: Mumbai | W13: 2023-06-04 | X13: 92
A14: S0007 | B14: Priya | C14: Roy | D14: Female | E14: 20 | F14: 9 | G14: C | H14: Hyderabad | I14: 2025-08-17 | J14: 88 | L14: Vikram | O14: S0010 | P14: Arjun | Q14: Roy | R14: Female | S14: 15 | T14: 9 | U14: C | V14: Pune | W14: 2025-03-19 | X14: 90
A15: S0008 | B15: Neha | C15: Paul | D15: Male | E15: 19 | F15: 12 | G15: A | H15: Mumbai | I15: 2025-01-28 | J15: 60 | L15: Pooja | O15: S0011 | P15: Riya | Q15: Gupta | R15: Female | S15: 20 | T15: 10 | U15: D | V15: Hyderabad | W15: 2024-10-08 | X15: 59
A16: S0009 | B16: Amit | C16: Singh | D16: Female | E16: 19 | F16: 12 | G16: B | H16: Mumbai | I16: 2023-06-04 | J16: 92 | L16: Rahul | O16: S0012 | P16: Arjun | Q16: Patel | R16: Male | S16: 14 | T16: 12 | U16: A | V16: Hyderabad | W16: 2024-08-18 | X16: 43
A17: S0010 | B17: Arjun | C17: Roy | D17: Female | E17: 15 | F17: 9 | G17: C | H17: Pune | I17: 2025-03-19 | J17: 90 | O17: S0013 | P17: Neha | Q17: Gupta | R17: Male | S17: 15 | T17: 12 | U17: B | V17: Delhi | W17: 2024-04-25 | X17: 51
A18: S0011 | B18: Riya | C18: Gupta | D18: Female | E18: 20 | F18: 10 | G18: D | H18: Hyderabad | I18: 2024-10-08 | J18: 59 | O18: S0014 | P18: Sneha | Q18: Gupta | R18: Male | S18: 16 | T18: 10 | U18: D | V18: Kolkata | W18: 2023-04-30 | X18: 42
A19: S0012 | B19: Arjun | C19: Patel | D19: Male | E19: 14 | F19: 12 | G19: A | H19: Hyderabad | I19: 2024-08-18 | J19: 43 | O19: S0015 | P19: Karan | Q19: Singh | R19: Male | S19: 20 | T19: 12 | U19: B | V19: Hyderabad | W19: 2024-02-05 | X19: 62
A20: S0013 | B20: Neha | C20: Gupta | D20: Male | E20: 15 | F20: 12 | G20: B | H20: Delhi | I20: 2024-04-25 | J20: 51 | O20: S0016 | P20: Vikram | Q20: Das | R20: Male | S20: 20 | T20: 9 | U20: B | V20: Jaipur | W20: 2025-08-10 | X20: 55
A21: S0014 | B21: Sneha | C21: Gupta | D21: Male | E21: 16 | F21: 10 | G21: D | H21: Kolkata | I21: 2023-04-30 | J21: 42 | O21: S0017 | P21: Arjun | Q21: Kumar | R21: Male | S21: 14 | T21: 12 | U21: D | V21: Bengaluru | W21: 2023-09-19 | X21: 42
A22: S0015 | B22: Karan | C22: Singh | D22: Male | E22: 20 | F22: 12 | G22: B | H22: Hyderabad | I22: 2024-02-05 | J22: 62 | O22: S0018 | P22: Pooja | Q22: Patel | R22: Female | S22: 19 | T22: 9 | U22: A | V22: Mumbai | W22: 2024-05-30 | X22: 76
A23: S0016 | B23: Vikram | C23: Das | D23: Male | E23: 20 | F23: 9 | G23: B | H23: Jaipur | I23: 2025-08-10 | J23: 55 | O23: S0019 | P23: Priya | Q23: Patel | R23: Female | S23: 17 | T23: 12 | U23: A | V23: Chennai | W23: 2025-04-12 | X23: 66
A24: S0017 | B24: Arjun | C24: Kumar | D24: Male | E24: 14 | F24: 12 | G24: D | H24: Bengaluru | I24: 2023-09-19 | J24: 42 | O24: S0020 | P24: Vikram | Q24: Ghosh | R24: Female | S24: 15 | T24: 10 | U24: B | V24: Jaipur | W24: 2023-11-01 | X24: 59
A25: S0018 | B25: Pooja | C25: Patel | D25: Female | E25: 19 | F25: 9 | G25: A | H25: Mumbai | I25: 2024-05-30 | J25: 76 | O25: S0021 | P25: Priya | Q25: Patel | R25: Female | S25: 19 | T25: 9 | U25: B | V25: Delhi | W25: 2025-08-12 | X25: 50
A26: S0019 | B26: Priya | C26: Patel | D26: Female | E26: 17 | F26: 12 | G26: A | H26: Chennai | I26: 2025-04-12 | J26: 66 | O26: S0022 | P26: Rahul | Q26: Sharma | R26: Female | S26: 16 | T26: 9 | U26: C | V26: Bengaluru | W26: 2025-02-24 | X26: 52
A27: S0020 | B27: Vikram | C27: Ghosh | D27: Female | E27: 15 | F27: 10 | G27: B | H27: Jaipur | I27: 2023-11-01 | J27: 59 | O27: S0023 | P27: Amit | Q27: Paul | R27: Male | S27: 20 | T27: 12 | U27: A | V27: Kolkata | W27: 2024-05-03 | X27: 86
A28: S0021 | B28: Priya | C28: Patel | D28: Female | E28: 19 | F28: 9 | G28: B | H28: Delhi | I28: 2025-08-12 | J28: 50 | O28: S0024 | P28: Vikram | Q28: Sharma | R28: Female | S28: 16 | T28: 9 | U28: C | V28: Jaipur | W28: 2025-08-25 | X28: 52
... A504: S0497 | B504: Amit | C504: Paul | D504: Male | E504: 20 | F504: 11 | G504: C | H504: Mumbai | I504: 2024-10-15 | J504: 94 | O504: S0500 | P504: Arjun | Q504: Mishra | R504: Female | S504: 18 | T504: 9 | U504: C | V504: Chennai | W504: 2023-08-05 | X504: 36
A505: S0498 | B505: Pooja | C505: Sharma | D505: Female | E505: 16 | F505: 10 | G505: D | H505: Chennai | I505: 2024-11-01 | J505: 90
A506: S0499 | B506: Amit | C506: Patel | D506: Male | E506: 16 | F506: 12 | G506: D | H506: Kolkata | I506: 2025-06-05 | J506: 41
A507: S0500 | B507: Arjun | C507: Mishra | D507: Female | E507: 18 | F507: 9 | G507: C | H507: Chennai | I507: 2023-08-05 | J507: 36

Sheet pivottables
A1: 9. Create a Pivot Table showing:
B3: Average Marks by City. | F3: Student Count by Gender. | J3: Average Age by Class. | N3: Total Students by City and Gender. | S3: Highest Marks by Class.
B5: Row Labels | C5: Average of Marks | F5: Row Labels | G5: Count of Student_ID | J5: Row Labels | K5: Average of Age | N5: Count of Student_ID | O5: Column Labels | S5: Row Labels | T5: Max of Marks
B6: Bengaluru | C6: 66.844828 | F6: Female | G6: 271 | J6: 9 | K6: 17.021429 | N6: Row Labels | O6: Female | P6: Male | Q6: Grand Total | S6: 9 | T6: 100
B7: Chennai | C7: 66.681818 | F7: Male | G7: 229 | J7: 10 | K7: 17.13913 | N7: Bengaluru | O7: 36 | P7: 22 | Q7: 58 | S7: 10 | T7: 100
B8: Delhi | C8: 66.697368 | F8: Grand Total | G8: 500 | J8: 11 | K8: 16.923729 | N8: Chennai | O8: 41 | P8: 25 | Q8: 66 | S8: 11 | T8: 100
B9: Hyderabad | C9: 65.140625 | J9: 12 | K9: 16.826772 | N9: Delhi | O9: 45 | P9: 31 | Q9: 76 | S9: 12 | T9: 100
B10: Jaipur | C10: 69.951613 | J10: Grand Total | K10: 16.976 | N10: Hyderabad | O10: 35 | P10: 29 | Q10: 64 | S10: Grand Total | T10: 100
B11: Kolkata | C11: 65.052632 | N11: Jaipur | O11: 31 | P11: 31 | Q11: 62
B12: Mumbai | C12: 66.666667 | N12: Kolkata | O12: 32 | P12: 25 | Q12: 57
B13: Pune | C13: 64.4375 | N13: Mumbai | O13: 30 | P13: 39 | Q13: 69
B14: Grand Total | C14: 66.508 | N14: Pune | O14: 21 | P14: 27 | Q14: 48
N15: Grand Total | O15: 271 | P15: 229 | Q15: 500
B22: Row Labels | C22: Count of Student_ID | F22: Row Labels | G22: Average of Marks
B23: Pune | C23: 48 | F23: 9 | G23: 65.442857
B24: Kolkata | C24: 57 | F24: 12 | G24: 65.937008
B25: Bengaluru | C25: 58 | F25: 10 | G25: 66.295652
B26: Jaipur | C26: 62 | F26: 11 | G26: 68.59322
B27: Hyderabad | C27: 64 | F27: Grand Total | G27: 66.508
B28: Chennai | C28: 66
B29: Mumbai | C29: 69
B30: Delhi | C30: 76
B31: Grand Total | C31: 500

Sheet dashboard
A1: 1. Create a dashboard containing:
B3: Total Students | I3: Total Students | J3: Average Marks | K3: Highest Marks | L3: Lowest Marks
B4: Average Marks | I4: 500 | J4: 66.508 | K4: 100 | L4: 35
B5: Highest Marks
B6: Lowest Marks
B7: Gender Distribution Chart
B8: City-wise Student Count
B9: Class-wise Average Marks

Sheet class_details
A1: Class | B1: Fees
A2: 9 | B2: 1000
A3: 10 | B3: 1200
A4: 11 | B4: 1500 | P4: fees(1) | Q4: is calculated using vlookup function
A5: 12 | B5: 1800 | P5: fees(2) | Q5: is calculated by index and match function
P6: fees(3) | Q6: is calculated by xlookup function
A7: Student_ID | B7: First_Name | C7: Last_Name | D7: Gender | E7: Age | F7: Class | G7: Section | H7: City | I7: Admission_Date | J7: Marks | K7: fees(1) | L7: fees(2) | M7: fees(3)
A8: S0001 | B8: Sneha | C8: Paul | D8: Male | E8: 16 | F8: 10 | G8: B | H8: Pune | I8: 2024-10-06 | J8: 37 | K8: =VLOOKUP($F8,$A$1:$B$5,2,0) -> 1200 | L8: =INDEX($B$2:$B$5,MATCH($F8,$A$2:$A$5,0)) -> 1200 | M8: =_xlfn.XLOOKUP($F8,$A$2:$A$5,$B$2:$B$5) -> 1200
A9: S0002 | B9: Amit | C9: Das | D9: Male | E9: 15 | F9: 12 | G9: B | H9: Jaipur | I9: 2024-11-06 | J9: 98 | K9: =VLOOKUP($F9,$A$1:$B$5,2,0) -> 1800 | L9: =INDEX($B$2:$B$5,MATCH($F9,$A$2:$A$5,0)) -> 1800 | M9: =_xlfn.XLOOKUP($F9,$A$2:$A$5,$B$2:$B$5) -> 1800
A10: S0003 | B10: Karan | C10: Roy | D10: Male | E10: 14 | F10: 12 | G10: D | H10: Kolkata | I10: 2024-10-12 | J10: 38 | K10: =VLOOKUP($F10,$A$1:$B$5,2,0) -> 1800 | L10: =INDEX($B$2:$B$5,MATCH($F10,$A$2:$A$5,0)) -> 1800 | M10: =_xlfn.XLOOKUP($F10,$A$2:$A$5,$B$2:$B$5) -> 1800
A11: S0004 | B11: Priya | C11: Singh | D11: Female | E11: 20 | F11: 9 | G11: A | H11: Kolkata | I11: 2023-06-14 | J11: 84 | K11: =VLOOKUP($F11,$A$1:$B$5,2,0) -> 1000 | L11: =INDEX($B$2:$B$5,MATCH($F11,$A$2:$A$5,0)) -> 1000 | M11: =_xlfn.XLOOKUP($F11,$A$2:$A$5,$B$2:$B$5) -> 1000
A12: S0005 | B12: Neha | C12: Kumar | D12: Female | E12: 17 | F12: 10 | G12: A | H12: Bengaluru | I12: 2023-09-21 | J12: 45 | K12: =VLOOKUP($F12,$A$1:$B$5,2,0) -> 1200 | L12: =INDEX($B$2:$B$5,MATCH($F12,$A$2:$A$5,0)) -> 1200 | M12: =_xlfn.XLOOKUP($F12,$A$2:$A$5,$B$2:$B$5) -> 1200
A13: S0006 | B13: Sneha | C13: Paul | D13: Female | E13: 19 | F13: 10 | G13: B | H13: Hyderabad | I13: 2023-09-12 | J13: 36 | K13: =VLOOKUP($F13,$A$1:$B$5,2,0) -> 1200 | L13: =INDEX($B$2:$B$5,MATCH($F13,$A$2:$A$5,0)) -> 1200 | M13: =_xlfn.XLOOKUP($F13,$A$2:$A$5,$B$2:$B$5) -> 1200
A14: S0007 | B14: Priya | C14: Roy | D14: Female | E14: 20 | F14: 9 | G14: C | H14: Hyderabad | I14: 2025-08-17 | J14: 88 | K14: =VLOOKUP($F14,$A$1:$B$5,2,0) -> 1000 | L14: =INDEX($B$2:$B$5,MATCH($F14,$A$2:$A$5,0)) -> 1000 | M14: =_xlfn.XLOOKUP($F14,$A$2:$A$5,$B$2:$B$5) -> 1000
A15: S0008 | B15: Neha | C15: Paul | D15: Male | E15: 19 | F15: 12 | G15: A | H15: Mumbai | I15: 2025-01-28 | J15: 60 | K15: =VLOOKUP($F15,$A$1:$B$5,2,0) -> 1800 | L15: =INDEX($B$2:$B$5,MATCH($F15,$A$2:$A$5,0)) -> 1800 | M15: =_xlfn.XLOOKUP($F15,$A$2:$A$5,$B$2:$B$5) -> 1800
A16: S0009 | B16: Amit | C16: Singh | D16: Female | E16: 19 | F16: 12 | G16: B | H16: Mumbai | I16: 2023-06-04 | J16: 92 | K16: =VLOOKUP($F16,$A$1:$B$5,2,0) -> 1800 | L16: =INDEX($B$2:$B$5,MATCH($F16,$A$2:$A$5,0)) -> 1800 | M16: =_xlfn.XLOOKUP($F16,$A$2:$A$5,$B$2:$B$5) -> 1800
A17: S0010 | B17: Arjun | C17: Roy | D17: Female | E17: 15 | F17: 9 | G17: C | H17: Pune | I17: 2025-03-19 | J17: 90 | K17: =VLOOKUP($F17,$A$1:$B$5,2,0) -> 1000 | L17: =INDEX($B$2:$B$5,MATCH($F17,$A$2:$A$5,0)) -> 1000 | M17: =_xlfn.XLOOKUP($F17,$A$2:$A$5,$B$2:$B$5) -> 1000
A18: S0011 | B18: Riya | C18: Gupta | D18: Female | E18: 20 | F18: 10 | G18: D | H18: Hyderabad | I18: 2024-10-08 | J18: 59 | K18: =VLOOKUP($F18,$A$1:$B$5,2,0) -> 1200 | L18: =INDEX($B$2:$B$5,MATCH($F18,$A$2:$A$5,0)) -> 1200 | M18: =_xlfn.XLOOKUP($F18,$A$2:$A$5,$B$2:$B$5) -> 1200
A19: S0012 | B19: Arjun | C19: Patel | D19: Male | E19: 14 | F19: 12 | G19: A | H19: Hyderabad | I19: 2024-08-18 | J19: 43 | K19: =VLOOKUP($F19,$A$1:$B$5,2,0) -> 1800 | L19: =INDEX($B$2:$B$5,MATCH($F19,$A$2:$A$5,0)) -> 1800 | M19: =_xlfn.XLOOKUP($F19,$A$2:$A$5,$B$2:$B$5) -> 1800
... A507: S0500 | B507: Arjun | C507: Mishra | D507: Female | E507: 18 | F507: 9 | G507: C | H507: Chennai | I507: 2023-08-05 | J507: 36 | K507: =VLOOKUP($F507,$A$1:$B$5,2,0) -> 1000 | L507: =INDEX($B$2:$B$5,MATCH($F507,$A$2:$A$5,0)) -> 1000 | M507: =_xlfn.XLOOKUP($F507,$A$2:$A$5,$B$2:$B$5) -> 1000
